<?xml version="1.0"?>
<robot name="servomotor_diff_robot" xmlns:xacro="http://ros.org/wiki/xacro">
  <xacro:arg name="pi" default="3.14159"/>
  <xacro:include filename="$(find my_ugv_description)/urdf/servomotor_diff_robot_gazebo.xacro"/>

  <!-- Robot Gazebo Controller -->
  <xacro:servomotor_controller />


  <link name="base_footprint"/>

  <joint name="base_joint" type="fixed">
    <parent link="base_footprint"/>
    <child link="base_link"/>
    <origin xyz="0 0 0.15" rpy="0 0 0"/>
  </joint>
  
  <link name="base_link">
    <visual>
      <origin xyz="-0.03 0 0.12" rpy="0 0 0"/>
      <geometry>
        <box size="0.80 0.60 0.15" />
      </geometry>
    </visual>
    <collision>
      <origin xyz="-0.03 0 0.12" rpy="0 0 0"/>
      <geometry>
        <box size="0.7 0.55 0.12"/>
      </geometry>
    </collision>
    <inertial>
      <origin xyz="0 0 0.1" rpy="0 0 0"/> <!-- Note: A plugin is used to move the robot. To stabilize the mobile robot due to the servo_ link has inertia, a larger mass and inertia are used -->
      <mass value="5"/>
      <inertia ixx=".006" ixy="0" ixz="0"
               iyy=".003375" iyz="0"
               izz=".096" />
    </inertial>
  </link>

  <!-- Wheels definition (joints and links) -->
  <joint name="wheel_left_joint" type="continuous">
    <parent link="base_link"/>
    <child link="wheel_left_link"/>
    <origin xyz=".20 0.33 0.09" rpy="0 0 0"/>
    <axis xyz="0 1 0"/>
  </joint>
  <link name="wheel_left_link">
    <visual>
      <origin xyz="0 0 0" rpy="1.5707 0 0"/>
      <geometry>
         <cylinder radius="0.12" length="0.05"/>
      </geometry>
    </visual>
    <collision>
      <origin xyz="0 0 .12" rpy="0 0 0"/>
      <geometry>
      <cylinder radius="0.12" length="0.05"/>
      </geometry>
    </collision>
    <inertial>
      <origin xyz="0 0 0" />
      <mass value="1" />
      <inertia ixx=".0038" ixy="0" ixz="0"
               iyy=".0038" iyz="0"
               izz=".0072" />
      </inertial>
  </link>

  <joint name="wheel_right_joint" type="continuous">
    <parent link="base_link"/>
    <child link="wheel_right_link"/>
    <origin xyz=".20 -0.33 .09" rpy="0 0 0"/>
    <axis xyz="0 1 0"/>
  </joint>
  
  <link name="wheel_right_link">
    <visual>
      <origin xyz="0 0 0" rpy="1.57 0 0"/>
      <geometry>
        <cylinder radius="0.12" length="0.05"/>
      </geometry>
    </visual>
    <collision>
      <origin xyz="0 0 .12" rpy="0 0 0"/>
      <geometry>
        <cylinder radius="0.12" length="0.05"/>
      </geometry>
    </collision>
    <inertial>
      <origin xyz="0 0 0" />
      <mass value="1" />
      <inertia ixx=".0038" ixy="0" ixz="0"
               iyy=".0038" iyz="0"
               izz=".0072" />
      </inertial>
  </link>

  <!-- Caster wheel definition (joint and link) -->
  <joint name="caster_joint" type="fixed">
    <parent link="base_link"/>
    <child link="caster_link"/>
    <origin xyz="-0.32 0 .02" rpy="0 0 0"/>
  </joint>
  <link name="caster_link">
    <visual>
      <origin xyz="0 0 .02" rpy="0 0 0"/>
      <geometry>
        <sphere radius="0.04"/>
      </geometry>
    </visual>
    <collision>
      <origin xyz="0 0 0" rpy="0 0 0"/>
      <geometry>
        <sphere radius="0.04"/>
      </geometry>
    </collision>
    <inertial>
      <origin xyz="0 0 0" />
      <mass value=".3" />
      <inertia ixx=".00019" ixy="0" ixz="0" iyy="0.00019" iyz="0" izz=".00019" />
    </inertial>
  </link>


  <!-- conveyor and CAMERA definition -->
  <!-- Conveyor (joint, link and transmission) -->
  <joint name="servo_joint" type="prismatic">
    <origin xyz="0.35 0 0.25" rpy="0 0 0"/>
    <parent link="base_link"/>
    <child link="servo_link"/>
    <axis xyz="1 0 0"/>
    <dynamics damping="0.001" friction="0.0"/> 
   <limit effort="1000.0" lower="-0.7" upper="0" velocity="0.5"/> 
  </joint>

  <link name="servo_link">
    <visual>
      <origin xyz="0 0 0" rpy="0 0 0"/>
      <geometry>
        <box size="0.09 0.58 0.09"/>
      </geometry>
      <material name="orange"/> <!--Color in RViz-->
    </visual>

    <collision>
      <origin xyz="0 0 0" rpy="0 0 0"/>
      <geometry>
        <box size="0.09 0.58 0.09"/>
      </geometry>
    </collision>

    <inertial> <!-- The inertial tag must be correctly set up to obtain the desired link behavior -->
      <origin xyz="0 0 0" />
      <mass value="0.1" />
      <inertia ixx=".00013" ixy="0" ixz="0" iyy=".0028" iyz="0" izz=".0028" />
    </inertial>
  </link>

  <transmission name="tran">
    <type>transmission_interface/SimpleTransmission</type>
    <joint name="servo_joint">
      <hardwareInterface>hardware_interface/EffortJointInterface</hardwareInterface>
    </joint>
    <actuator name="motor">
      <hardwareInterface>hardware_interface/EffortJointInterface</hardwareInterface>
      <mechanicalReduction>1</mechanicalReduction><!-- This tag does not any change in simulation -->
    </actuator>
  </transmission>


  <!-- The joint and link of the camera. Note: Both link name and joint name must be the same as the ones used in the plugin -->
  <joint name="camera_rgb_optical_joint" type="fixed">
    <origin xyz="0.4 0 .12" rpy="0 0 0"/> <!-- X axis is considered as the optical axis -->
    <parent link="base_link"/> 
    <child link="camera_rgb_frame"/>
  </joint>
  <link name="camera_rgb_frame">
    <visual>
      <origin xyz="0 0 0" rpy="0 0 0"/>
      <geometry>
        <box size="0.05 0.05 0.05"/>
      </geometry>
      <material name="orange"/> <!--Color in RViz-->
    </visual>
 

    <collision>
      <origin xyz="0 0 0" rpy="0 0 0"/>
      <geometry>
        <box size="0.05 0.05 0.05"/>
      </geometry>
    </collision>
    <!-- Since a sensor is used, the inertial tag can be ommited -->
  </link>

</robot>
